Workbook

Sheet BirdPhotos
A1: Filename | B1: AuditedName | C1: Taxon Order | D1: English Name | E1: French Name | F1: Latin Name | G1: Order | H1: Family
A2: Acadian_Flycatcher_2313.jpg | B2: Acadian Flycatcher | C2: =VLOOKUP(B2,LifeList!$E$2:$J$2038,6) -> 16950 | D2: =VLOOKUP(B2,LifeList!$E$2:$G$2038,1) -> Acadian Flycatcher | E2: =VLOOKUP(B2,LifeList!$E$2:$G$2038,2) -> Moucherolle vert | F2: =VLOOKUP(B2,LifeList!$E$2:$G$2038,3) -> Empidonax virescens | G2: =VLOOKUP(B2,LifeList!$E$2:$I$2038,4) -> Passeriformes | H2: =VLOOKUP(B2,LifeList!$E$2:$I$2038,5) -> Tyrannidae (Tyrant Flycatchers)
A3: Acorn_woodpecker_2152.jpg | B3: Acorn Woodpecker | C3: =VLOOKUP(B3,LifeList!$E$2:$J$2038,6) -> 11146 | D3: =VLOOKUP(B3,LifeList!$E$2:$G$2038,1) -> Acorn Woodpecker | E3: =VLOOKUP(B3,LifeList!$E$2:$G$2038,2) -> Pic glandivore | F3: =VLOOKUP(B3,LifeList!$E$2:$G$2038,3) -> Melanerpes formicivorus | G3: =VLOOKUP(B3,LifeList!$E$2:$I$2038,4) -> Piciformes | H3: =VLOOKUP(B3,LifeList!$E$2:$I$2038,5) -> Picidae (Woodpeckers)
A4: Acorn_Woodpecker_2305.jpg | B4: Acorn Woodpecker | C4: =VLOOKUP(B4,LifeList!$E$2:$J$2038,6) -> 11146 | D4: =VLOOKUP(B4,LifeList!$E$2:$G$2038,1) -> Acorn Woodpecker | E4: =VLOOKUP(B4,LifeList!$E$2:$G$2038,2) -> Pic glandivore | F4: =VLOOKUP(B4,LifeList!$E$2:$G$2038,3) -> Melanerpes formicivorus | G4: =VLOOKUP(B4,LifeList!$E$2:$I$2038,4) -> Piciformes | H4: =VLOOKUP(B4,LifeList!$E$2:$I$2038,5) -> Picidae (Woodpeckers)
A5: Acorn_Woodpecker_5803.jpg | B5: Acorn Woodpecker | C5: =VLOOKUP(B5,LifeList!$E$2:$J$2038,6) -> 11146 | D5: =VLOOKUP(B5,LifeList!$E$2:$G$2038,1) -> Acorn Woodpecker | E5: =VLOOKUP(B5,LifeList!$E$2:$G$2038,2) -> Pic glandivore | F5: =VLOOKUP(B5,LifeList!$E$2:$G$2038,3) -> Melanerpes formicivorus | G5: =VLOOKUP(B5,LifeList!$E$2:$I$2038,4) -> Piciformes | H5: =VLOOKUP(B5,LifeList!$E$2:$I$2038,5) -> Picidae (Woodpeckers)
A6: African Cuckoo-Hawk-4865.jpg | B6: African Cuckoo-Hawk | C6: =VLOOKUP(B6,LifeList!$E$2:$J$2038,6) -> 7875 | D6: =VLOOKUP(B6,LifeList!$E$2:$G$2038,1) -> African Cuckoo-Hawk | E6: =VLOOKUP(B6,LifeList!$E$2:$G$2038,2) -> Baza coucou | F6: =VLOOKUP(B6,LifeList!$E$2:$G$2038,3) -> Aviceda cuculoides | G6: =VLOOKUP(B6,LifeList!$E$2:$I$2038,4) -> Accipitriformes | H6: =VLOOKUP(B6,LifeList!$E$2:$I$2038,5) -> Accipitridae (Hawks, Eagles, and Kites)
A7: African Hawk-Eagle-6342.jpg | B7: African Hawk-Eagle | C7: =VLOOKUP(B7,LifeList!$E$2:$J$2038,6) -> 8075 | D7: =VLOOKUP(B7,LifeList!$E$2:$G$2038,1) -> African Hawk-Eagle | E7: =VLOOKUP(B7,LifeList!$E$2:$G$2038,2) -> Aigle fascié | F7: =VLOOKUP(B7,LifeList!$E$2:$G$2038,3) -> Aquila spilogaster | G7: =VLOOKUP(B7,LifeList!$E$2:$I$2038,4) -> Accipitriformes | H7: =VLOOKUP(B7,LifeList!$E$2:$I$2038,5) -> Accipitridae (Hawks, Eagles, and Kites)
A8: African Jacana-3938.jpg | B8: African Jacana | C8: =VLOOKUP(B8,LifeList!$E$2:$J$2038,6) -> 6005 | D8: =VLOOKUP(B8,LifeList!$E$2:$G$2038,1) -> African Jacana | E8: =VLOOKUP(B8,LifeList!$E$2:$G$2038,2) -> Jacana à poitrine dorée | F8: =VLOOKUP(B8,LifeList!$E$2:$G$2038,3) -> Actophilornis africanus | G8: =VLOOKUP(B8,LifeList!$E$2:$I$2038,4) -> Charadriiformes | H8: =VLOOKUP(B8,LifeList!$E$2:$I$2038,5) -> Jacanidae (Jacanas)
A9: African Sacred Ibis-5733.jpg | B9: African Sacred Ibis | C9: =VLOOKUP(B9,LifeList!$E$2:$J$2038,6) -> 7491 | D9: =VLOOKUP(B9,LifeList!$E$2:$G$2038,1) -> African Sacred Ibis | E9: =VLOOKUP(B9,LifeList!$E$2:$G$2038,2) -> Ibis sacré | F9: =VLOOKUP(B9,LifeList!$E$2:$G$2038,3) -> Threskiornis aethiopicus | G9: =VLOOKUP(B9,LifeList!$E$2:$I$2038,4) -> Pelecaniformes | H9: =VLOOKUP(B9,LifeList!$E$2:$I$2038,5) -> Threskiornithidae (Ibises and Spoonbills)
A10: African Woolly-necked Stork-4142.jpg | B10: African Woolly-necked Stork | C10: =VLOOKUP(B10,LifeList!$E$2:$J$2038,6) -> 7285 | D10: =VLOOKUP(B10,LifeList!$E$2:$G$2038,1) -> African Woolly-necked Stork | E10: =VLOOKUP(B10,LifeList!$E$2:$G$2038,2) -> Cigogne à pattes noires | F10: =VLOOKUP(B10,LifeList!$E$2:$G$2038,3) -> Ciconia microscelis | G10: =VLOOKUP(B10,LifeList!$E$2:$I$2038,4) -> Ciconiiformes | H10: =VLOOKUP(B10,LifeList!$E$2:$I$2038,5) -> Ciconiidae (Storks)
A11: African_Black-headed_Oriole_3391.jpg | B11: African Black-headed Oriole | C11: =VLOOKUP(B11,LifeList!$E$2:$J$2038,6) -> 19676 | D11: =VLOOKUP(B11,LifeList!$E$2:$G$2038,1) -> African Black-headed Oriole | E11: =VLOOKUP(B11,LifeList!$E$2:$G$2038,2) -> Loriot masqué | F11: =VLOOKUP(B11,LifeList!$E$2:$G$2038,3) -> Oriolus larvatus | G11: =VLOOKUP(B11,LifeList!$E$2:$I$2038,4) -> Passeriformes | H11: =VLOOKUP(B11,LifeList!$E$2:$I$2038,5) -> Oriolidae (Old World Orioles)
A12: African_Darter_6406.jpg | B12: African Darter | C12: =VLOOKUP(B12,LifeList!$E$2:$J$2038,6) -> 7370 | D12: =VLOOKUP(B12,LifeList!$E$2:$G$2038,1) -> African Darter | E12: =VLOOKUP(B12,LifeList!$E$2:$G$2038,2) -> Anhinga d'Afrique | F12: =VLOOKUP(B12,LifeList!$E$2:$G$2038,3) -> Anhinga rufa | G12: =VLOOKUP(B12,LifeList!$E$2:$I$2038,4) -> Suliformes | H12: =VLOOKUP(B12,LifeList!$E$2:$I$2038,5) -> Anhingidae (Anhingas)
A13: African_Fish-Eagle_6468.jpg | B13: African Fish-Eagle | C13: =VLOOKUP(B13,LifeList!$E$2:$J$2038,6) -> 8374 | D13: =VLOOKUP(B13,LifeList!$E$2:$G$2038,1) -> African Fish-Eagle | E13: =VLOOKUP(B13,LifeList!$E$2:$G$2038,2) -> Pygargue vocifer | F13: =VLOOKUP(B13,LifeList!$E$2:$G$2038,3) -> Icthyophaga vocifer | G13: =VLOOKUP(B13,LifeList!$E$2:$I$2038,4) -> Accipitriformes | H13: =VLOOKUP(B13,LifeList!$E$2:$I$2038,5) -> Accipitridae (Hawks, Eagles, and Kites)
... A4329: Zeledons_Antbird_5912.jpg | B4329: Zeledon's Antbird | C4329: =VLOOKUP(B4329,LifeList!$E$2:$J$2038,6) -> 14055 | D4329: =VLOOKUP(B4329,LifeList!$E$2:$G$2038,1) -> Zeledon's Antbird | E4329: =VLOOKUP(B4329,LifeList!$E$2:$G$2038,2) -> Alapi de Zeledon | F4329: =VLOOKUP(B4329,LifeList!$E$2:$G$2038,3) -> Hafferia zeledoni | G4329: =VLOOKUP(B4329,LifeList!$E$2:$I$2038,4) -> Passeriformes | H4329: =VLOOKUP(B4329,LifeList!$E$2:$I$2038,5) -> Thamnophilidae (Typical Antbirds)

Sheet LifeList
A1: Old Order | B1: Current order | C1: Taxon Order | D1: Category | E1: English Name | F1: French Name | G1: Scientific Name | H1: Order | I1: Family | J1: Taxon | K1: Location | L1: S/P | M1: Date | N1: LocID | O1: SubID | P1: Exotic | Q1: Countable
A2: 1058 | B2: 1186 | C2: 16950 | D2: species | E2: Acadian Flycatcher | F2: Moucherolle vert | G2: Empidonax virescens | H2: Passeriformes | I2: Tyrannidae (Tyrant Flycatchers) | J2: 16950 | K2: 8.6042x-80.0880 - Nov 13, 2016, 7:51 AM | L2: PA-8 | M2: 42687 | N2: L5079093 | O2: S32519336 | Q2: 1
A3: 1828 | B3: 865 | C3: 11146 | D3: species | E3: Acorn Woodpecker | F3: Pic glandivore | G3: Melanerpes formicivorus | H3: Piciformes | I3: Picidae (Woodpeckers) | J3: 11146 | K3: Orange Walk | L3: BZ-OW | M3: 40873 | N3: L295270 | O3: S15368874 | Q3: 1
A4: 1457 | B4: 1348 | C4: 19676 | D4: species | E4: African Black-headed Oriole | F4: Loriot masqué | G4: Oriolus larvatus | H4: Passeriformes | I4: Oriolidae (Old World Orioles) | J4: 19676 | K4: Kruger NP--Letaba-Olifants Rd | L4: ZA-LP | M4: 41907 | N4: L2355950 | O4: S20317879 | Q4: 1
A5: 1356 | B5: 649 | C5: 7875 | D5: species | E5: African Cuckoo-Hawk | F5: Baza coucou | G5: Aviceda cuculoides | H5: Accipitriformes | I5: Accipitridae (Hawks, Eagles, and Kites) | J5: 7875 | K5: St Lucia--iMfolozi River mouth | L5: ZA-NL | M5: 41916 | N5: L4209873 | O5: S20614058 | Q5: 1
A6: 1416 | B6: 560 | C6: 7370 | D6: species | E6: African Darter | F6: Anhinga d'Afrique | G6: Anhinga rufa | H6: Suliformes | I6: Anhingidae (Anhingas) | J6: 7370 | K6: Kruger NP--southern section (please be more specific) | L6: ZA-MP | M6: 41910 | N6: L972510 | O6: S20390197 | Q6: 1
A7: 1405 | B7: 1697 | C7: 31416 | D7: species | E7: African Firefinch | F7: Amarante foncé | G7: Lagonosticta rubricata | H7: Passeriformes | I7: Estrildidae (Waxbills and Allies) | J7: 31416 | K7: Kruger NP--southern section (please be more specific) | L7: ZA-MP | M7: 41910 | N7: L972510 | O7: S20390197 | Q7: 1
A8: 1463 | B8: 692 | C8: 8374 | D8: species | E8: African Fish-Eagle | F8: Pygargue vocifer | G8: Icthyophaga vocifer | H8: Accipitriformes | I8: Accipitridae (Hawks, Eagles, and Kites) | J8: 8374 | K8: Kruger NP--Letaba-Olifants Rd | L8: ZA-LP | M8: 41907 | N8: L2355950 | O8: S20317879 | Q8: 1
A9: 1376 | B9: 1669 | C9: 30798 | D9: species | E9: African Golden-Weaver | F9: Tisserin jaune | G9: Ploceus subaureus | H9: Passeriformes | I9: Ploceidae (Weavers and Allies) | J9: 30798 | K9: St Lucia--iMfolozi River mouth | L9: ZA-NL | M9: 41914 | N9: L4209873 | O9: S20565478 | Q9: 1
A10: 1318 | B10: 675 | C10: 8118 | D10: species | E10: African Goshawk | F10: Autour tachiro | G10: Aerospiza tachiro | H10: Accipitriformes | I10: Accipitridae (Hawks, Eagles, and Kites) | J10: 8118 | K10: Moremi--Khwai River (north side) | L10: BW-NW | M10: 41925 | N10: L1220375 | O10: S20696955 | Q10: 1
A11: 1995 | B11: 1632 | C11: 28852 | D11: species | E11: African Gray Flycatcher | F11: Gobemouche à petit bec | G11: Bradornis microrhynchus | H11: Passeriformes | I11: Muscicapidae (Old World Flycatchers) | J11: 28852 | K11: Lake Manyara NP (Arusha) | L11: TZ-01 | M11: 38573 | N11: L1033409 | O11: S15379179 | Q11: 1
A12: 1908 | B12: 774 | C12: 9664 | D12: species | E12: African Gray Hornbill | F12: Calao à bec noir | G12: Lophoceros nasutus | H12: Bucerotiformes | I12: Bucerotidae (Hornbills) | J12: 9664 | K12: Erongo Lodge | L12: NA-ER | M12: 39245 | N12: L17656026 | O12: S102100868 | Q12: 1
A13: 1468 | B13: 161 | C13: 2548 | D13: species | E13: African Green-Pigeon | F13: Colombar à front nu | G13: Treron calvus | H13: Columbiformes | I13: Columbidae (Pigeons and Doves) | J13: 2548 | K13: Kruger NP--Letaba-Olifants Rd | L13: ZA-LP | M13: 41907 | N13: L2355950 | O13: S20317879 | Q13: 1
... A24: 2010 | B24: 582 | C24: 7491 | D24: species | E24: African Sacred Ibis | F24: Ibis sacré | G24: Threskiornis aethiopicus | H24: Pelecaniformes | I24: Threskiornithidae (Ibises and Spoonbills) | J24: 7491 | K24: Lake Manyara NP (Arusha) | L24: TZ-01 | M24: 38573 | N24: L1033409 | O24: S15379179 | Q24: 1
A25: 659 | B25: 1688 | C25: 31062 | D25: species | E25: African Silverbill | F25: Capucin bec-d'argent | G25: Euodice cantans | H25: Passeriformes | I25: Estrildidae (Waxbills and Allies) | J25: 31062 | K25: Francis H. I'i Brown North Course, Kamuela US-HI (19.9409,-155.8603) | L25: US-HI | M25: 43401 | N25: L8081156 | O25: S49516203 | P25: N | Q25: 1
A26: 1331 | B26: 501 | C26: 6620 | D26: species | E26: African Skimmer | F26: Bec-en-ciseaux d'Afrique | G26: Rynchops flavirostris | H26: Charadriiformes | I26: Laridae (Gulls, Terns, and Skimmers) | J26: 6620 | K26: Chobe River--west of Kasane | L26: BW-NW | M26: 41921 | N26: L2538778 | O26: S20699076 | Q26: 1
A27: 1466 | B27: 588 | C27: 7529 | D27: species | E27: African Spoonbill | F27: Spatule d'Afrique | G27: Platalea alba | H27: Pelecaniformes | I27: Threskiornithidae (Ibises and Spoonbills) | J27: 7529 | K27: Kruger NP--Letaba-Olifants Rd | L27: ZA-LP | M27: 41907 | N27: L2355950 | O27: S20317879 | Q27: 1
A28: 1390 | B28: 1644 | C28: 29690 | D28: species | E28: African Stonechat | F28: Monticole rocar | G28: Saxicola torquatus | H28: Passeriformes | I28: Muscicapidae (Old World Flycatchers) | J28: 29690 | K28: Ithala GR | L28: ZA-NL | M28: 41913 | N28: L3161131 | O28: S20535371 | Q28: 1
A29: 1347 | B29: 368 | C29: 5522 | D29: species | E29: African Swamphen | F29: Talève d'Afrique | G29: Porphyrio madagascariensis | H29: Gruiformes | I29: Rallidae (Rails, Gallinules, and Coots) | J29: 5522 | K29: Korsman Bird Sanctuary | L29: ZA-GT | M29: 41918 | N29: L1912725 | O29: S20305927 | Q29: 1
A30: 1429 | B30: 545 | C30: 7285 | D30: species | E30: African Woolly-necked Stork | F30: Cigogne à pattes noires | G30: Ciconia microscelis | H30: Ciconiiformes | I30: Ciconiidae (Storks) | J30: 7285 | K30: Kruger NP--Skukuza Camp (Camp only; please use more precise hotspots for drives) | L30: ZA-MP | M30: 41909 | N30: L951360 | O30: S20389946 | Q30: 1
A31: 354 | B31: 594 | C31: 7554 | D31: species | E31: Agami Heron | F31: Héron agami | G31: Agamia agami | H31: Pelecaniformes | I31: Ardeidae (Herons, Egrets, and Bitterns) | J31: 7554 | K31: Refugio mixto Caño Negro | L31: CR-A | M31: 44723 | N31: L691866 | O31: S112726151 | Q31: 1
A32: 638 | B32: 1733 | C32: 32129 | D32: species | E32: Akiapolaau | F32: Akiapolaau d'Hawaï | G32: Hemignathus wilsoni | H32: Passeriformes | I32: Fringillidae (Finches, Euphonias, and Allies) | J32: 32129 | K32: Pu'u O'o Trail, Kipuka Ainahou section (first 2 miles) | L32: US-HI | M32: 43405 | N32: L366605 | O32: S49612040 | Q32: 1
A33: 441 | B33: 1187 | C33: 16951 | D33: species | E33: Alder Flycatcher | F33: Moucherolle des aulnes | G33: Empidonax alnorum | H33: Passeriformes | I33: Tyrannidae (Tyrant Flycatchers) | J33: 16951 | K33: Osgoode, Ottawa CA-ON (45.2238,-75.6297) | L33: CA-ON | M33: 44049 | N33: L9160902 | O33: S72160828 | Q33: 1
A34: 626 | B34: 1700 | C34: 31480 | D34: species | E34: Alpine Accentor | F34: Accenteur alpin | G34: Prunella collaris | H34: Passeriformes | I34: Prunellidae (Accentors) | J34: 31480 | K34: Peisey-Nancroix (ville) | L34: FR-ARA | M34: 43492 | N34: L8433472 | O34: S52089497 | Q34: 1
C35: 4831 | D35: species | E35: Allen's Hummingbird | F35: Colibri d'Allen | G35: Selasphorus sasin | H35: Apodiformes | I35: Trochilidae (Hummingbirds) | J35: 4831 | K35: Mission Creek--SB Museum of Natural History | L35: US-CA | M35: 44117 | N35: L600095 | O35: S15451608
A36: 1780 | B36: 1832 | C36: 33755 | D36: species | E36: Altamira Oriole | F36: Oriole à gros bec | G36: Icterus gularis | H36: Passeriformes | I36: Icteridae (Troupials and Allies) | J36: 33755 | K36: Orange Walk | L36: BZ-OW | M36: 40873 | N36: L295270 | O36: S15368874 | Q36: 1
A37: 1830 | B37: 811 | C37: 10312 | D37: species | E37: Amazon Kingfisher | F37: Martin-pêcheur d'Amazonie | G37: Chloroceryle amazona | H37: Coraciiformes | I37: Alcedinidae (Kingfishers) | J37: 10312 | K37: Orange Walk | L37: BZ-OW | M37: 40873 | N37: L295270 | O37: S15368874 | Q37: 1
A38: 1143 | B38: 389 | C38: 5780 | D38: species | E38: American Avocet | F38: Avocette d'Amérique | G38: Recurvirostra americana | H38: Charadriiformes | I38: Recurvirostridae (Stilts and Avocets) | J38: 5780 | K38: Mersea Rd 2 west bridge | L38: CA-ON | M38: 42140 | N38: L3619669 | O38: S23478734 | Q38: 1
A39: 2027 | B39: 724 | C39: 8633 | D39: species | E39: American Barn Owl | F39: Effraie d'Amérique | G39: Tyto furcata | H39: Strigiformes | I39: Tytonidae (Barn-Owls) | J39: 8633 | K39: Santa Cruz--Área general (por favor usar un hotspot más específico) | L39: EC-W | M39: 38176 | N39: L471636 | O39: S15379722 | Q39: 1
A40: 1628 | B40: 595 | C40: 7560 | D40: species | E40: American Bittern | F40: Butor d'Amérique | G40: Botaurus lentiginosus | H40: Pelecaniformes | I40: Ardeidae (Herons, Egrets, and Bitterns) | J40: 7560 | K40: Marais 3 à 5 (Canards Illimités) | L40: CA-QC | M40: 41369 | N40: L1145146 | O40: S15364580 | Q40: 1
A41: 1585 | B41: 42 | C41: 571 | D41: species | E41: American Black Duck | F41: Canard noir | G41: Anas rubripes | H41: Anseriformes | I41: Anatidae (Ducks, Geese, and Waterfowl) | J41: 571 | K41: Britannia CA--Britannia Ridge | L41: CA-ON | M41: 41548 | N41: L1535778 | O41: S15359906 | Q41: 1
A42: 1852 | B42: 365 | C42: 5500 | D42: species | E42: American Coot | F42: Foulque d'Amérique | G42: Fulica americana | H42: Gruiformes | I42: Rallidae (Rails, Gallinules, and Coots) | J42: 5500 | K42: Orange Walk | L42: BZ-OW | M42: 40873 | N42: L295270 | O42: S15368874 | Q42: 1
A43: 1611 | B43: 1426 | C43: 21557 | D43: species | E43: American Crow | F43: Corneille d'Amérique | G43: Corvus brachyrhynchos | H43: Passeriformes | I43: Corvidae (Crows, Jays, and Magpies) | J43: 21557 | K43: Point Pelee NP* general (use more precise loc.) | L43: CA-ON | M43: 41396 | N43: L131153 | O43: S15364735 | Q43: 1
A44: 664 | B44: 1573 | C44: 27668 | D44: species | E44: American Dipper | F44: Cincle d'Amérique | G44: Cinclus mexicanus | H44: Passeriformes | I44: Cinclidae (Dippers) | J44: 27668 | K44: Burnaby Lake--Avalon entrance | L44: CA-BC | M44: 43393 | N44: L452571 | O44: S49326481 | Q44: 1
A45: 764 | B45: 516 | C45: 6807 | D45: species | E45: American Flamingo | F45: Flamant des Caraïbes | G45: Phoenicopterus ruber | H45: Phoenicopteriformes | I45: Phoenicopteridae (Flamingos) | J45: 6807 | K45: Playa Los Dos Compadres | L45: MX-ROO | M45: 43085 | N45: L3530195 | O45: S41139758 | Q45: 1
A46: 1111 | B46: 396 | C46: 5815 | D46: species | E46: American Golden-Plover | F46: Pluvier bronzé | G46: Pluvialis dominica | H46: Charadriiformes | I46: Charadriidae (Plovers and Lapwings) | J46: 5815 | K46: Hillman Marsh CA (general location) | L46: CA-ON | M46: 42498 | N46: L283720 | O46: S29500079 | Q46: 1
A47: 1658 | B47: 1748 | C47: 32617 | D47: species | E47: American Goldfinch | F47: Chardonneret jaune | G47: Spinus tristis | H47: Passeriformes | I47: Fringillidae (Finches, Euphonias, and Allies) | J47: 32617 | K47: Ottawa--MacDonald-Cartier International Airport (High Road) | L47: CA-ON | M47: 41079 | N47: L1217618 | O47: S15371413 | Q47: 1
... A159: 1253 | B159: 2002 | C159: 35281 | D159: species | E159: Black Flowerpiercer | F159: Percefleur noir | G159: Diglossa humeralis | H159: Passeriformes | I159: Thraupidae (Tanagers and Allies) | J159: 35281 | K159: PNN Los Nevados--Centro de Visitantes La Cueva | L159: CO-CAL | M159: 41990 | N159: L7895434 | O159: S20941471 | Q159: 1
A160: 645 | B160: 105 | C160: 1647 | D160: species | E160: Black Francolin | F160: Francolin noir | G160: Francolinus francolinus | H160: Galliformes | I160: Phasianidae (Pheasants, Grouse, and Allies) | J160: 1647 | K160: Road to Cement Plant Rd | L160: US-HI | M160: 43405 | N160: L1430537 | O160: S49602576 | P160: N | Q160: 1
A161: 1079 | B161: 79 | C161: 854 | D161: species | E161: Black Guan | F161: Pénélope unicolore | G161: Chamaepetes unicolor | H161: Galliformes | I161: Cracidae (Guans, Chachalacas, and Curassows) | J161: 854 | K161: Canopy Lodge | L161: PA-2 | M161: 42686 | N161: L604642 | O161: S32519275 | Q161: 1
...
